Workbook

Sheet Moggio
B1: Dati generali
B2: Asset | D2: Moggio
B3: Acquisto | C3: Valore immobile | D3: -65000 | E3: 46148 | F3: =EDATE(E3,($E$5)*12)-1 -> 55278
B4: Data acquisto | E4: 46148 | F4: =EDATE(E4,($E$5)*12)-1 -> 55278 | I4: IRR | J4: =$L$302 -> 0.93417179
B5: Anni investimento | E5: 25 | I5: NPV | J5: =MAX(300:300) -> 10671.016
B6: Acquisto da? | E6: Privato/Imprese
B7: Prima casa? | E7: NO
B8: Rendita catastale | C8: - | D8: 619.75 | E8: =$E$4 -> 46148 | F8: =EDATE(E8,$E$5*12)-1 -> 55278
B9: Rivalutazione | C9: - | D9: 0.005 | E9: =$E$4 -> 46148 | F9: =F4 -> 55278
B12: Ricavi
B13: Affitto | C13: Alloggio | D13: 3000 | E13: =$E$4 -> 46148 | F13: =EDATE(E13,$E$5*12)-1 -> 55278
B15: Vendita | C15: Alloggio | D15: =-$D$3*(1+D9)^E5 -> 73631.712 | E15: =EDATE($E$4,$E$5*12)-1 -> 55278 | F15: =EDATE($E$4,$E$5*12) -> 55279
B17: Costi
B18: Condominio | C18: Ordinario | D18: =1200 -> 1200 | E18: =$E$4 -> 46148 | F18: =EDATE(E18,$E$5*12)-1 -> 55278
B19: Assicurazione | C19: - | D19: 0 | E19: =$E$4 -> 46148 | F19: 46053
B20: Utenze | C20: Gas | D20: 0 | E20: =$E$4 -> 46148 | F20: =EDATE(E20,$E$5*12)-1 -> 55278
B21: Utenze | C21: Luce | D21: =-50*12 -> -600 | E21: =$E$4 -> 46148 | F21: =EDATE(E21,$E$5*12)-1 -> 55278
B22: Utenze | C22: Internet | D22: =-38.83*6 -> -232.98 | E22: =$E$4 -> 46148 | F22: =EDATE(E22,$E$5*12)-1 -> 55278
B23: Manutenzione ordinaria | C23: - | D23: -100 | E23: =$E$4 -> 46148 | F23: =EDATE(E23,$E$5*12)-1 -> 55278
B24: Manutenzione straordinaria | C24: - | D24: -200 | E24: =$E$4 -> 46148 | F24: =EDATE(E24,$E$5*12)-1 -> 55278
B27: Ammortamenti
B28: Anni | D28: =SUMIFS(#REF!,#REF!,$B28) -> #REF!
B30: Oneri finanziari
B35: Avviamento
B36: Avviamento | C36: Notaio | D36: -2000 | E36: =$E$4 -> 46148 | F36: =EDATE(E36,$E$5*12)-1 -> 55278
B37: Avviamento | C37: Intermediazione | D37: =-3000*1.22 -> -3660 | E37: =$E$4 -> 46148 | F37: =EDATE(E37,$E$5*12)-1 -> 55278
B38: Avviamento | C38: - | D38: -1000 | E38: =$E$4 -> 46148 | F38: =EDATE(E38,$E$5*12)-1 -> 55278
B39: Arredamento | C39: - | D39: -3000 | E39: =$E$4 -> 46148 | F39: =EDATE(E39,$E$5*12)-1 -> 55278
B40: Ristrutturazione | C40: - | D40: -5000 | E40: =$E$4 -> 46148 | F40: =EDATE(E40,$E$5*12)-1 -> 55278
B42: Tasse
B43: Imposte | C43: Registro | D43: =-IF($E$7="SI",MAX(2%*$D$8*105%*120,1000),MAX(9%*$D$8*105%*120,1000)) -> -7027.965 | E43: =$E$4 -> 46148 | F43: =EDATE(E43,$E$5*12)-1 -> 55278
B44: Imposte | C44: Ipotecaria | D44: =-IF($E$6="Privato/Imprese",50,200) -> -50 | E44: =$E$4 -> 46148 | F44: =EDATE(E44,$E$5*12)-1 -> 55278
B45: Imposte | C45: Catastale | D45: =-IF($E$6="Privato/Imprese",50,200) -> -50 | E45: =$E$4 -> 46148 | F45: =EDATE(E45,$E$5*12)-1 -> 55278
B47: Imposte | C47: IMU | D47: =IF($E$7="SI",0,$D$8*1.05*160*1.06%) -> 1103.6508 | E47: =$E$4 -> 46148 | F47: =EDATE(E47,$E$5*12)-1 -> 55278
B48: Imposte | C48: TARI | D48: -176 | E48: =$E$4 -> 46148 | F48: =EDATE(E48,$E$5*12)-1 -> 55278
B51: Detrazioni
B52: Mutuo | C52: Cap detrazione | D52: =4000*$D$31/294000 -> 0 | E52: Ripartizione mutuo
B53: Mutuo | C53: % detrazione | D53: 0.19
B54: Intermediazione | C54: Cap detrazione | D54: 1000
B55: Intermediazione | C55: % detrazione | D55: 0.19
...

Sheet Strambio
B1: Dati generali
B2: Asset | D2: Strambio
B3: Acquisto | C3: Valore immobile | D3: -420000 | E3: 44895 | F3: =EDATE(E3,($E$5)*12)-1 -> 55486
B4: Data acquisto | E4: 44895 | F4: =EDATE(E4,($E$5)*12)-1 -> 55486 | I4: IRR | J4: =$L$302 -> 0.025546688
B5: Anni investimento | E5: 29 | I5: NPV | J5: =MAX(300:300) -> 104702.56
B6: Acquisto da? | E6: Privato/Imprese
B7: Prima casa? | E7: SI
B8: Rendita catastale | C8: - | D8: =522.91+15.18 -> 538.09 | E8: =$E$4 -> 44895 | F8: =EDATE(E8,$E$5*12)-1 -> 55486
B9: Rivalutazione | C9: - | D9: 0 | E9: =$E$4 -> 44895 | F9: 44926
B10: Rivalutazione | C10: - | D10: 0.016 | E10: =F9+1 -> 44927 | F10: =F4 -> 55486
B12: Ricavi
B13: Affitto | C13: Alloggio | D13: =D14/12*8 -> 7200 | E13: 44986 | F13: 45291
B14: Affitto | C14: Alloggio | D14: =900*12 -> 10800 | E14: =F13+1 -> 45292 | F14: =F4 -> 55486
B15: Vendita | C15: Alloggio | D15: =-$D$3*(1+D10)^E5 -> 665528.75 | E15: =EDATE($E$4,$E$5*12)-1 -> 55486 | F15: =EDATE($E$4,$E$5*12) -> 55487
B17: Costi
B18: Avviamento | C18: - | E18: =$E$4 -> 44895 | F18: =EDATE(E18,$E$5*12)-1 -> 55486
B19: Condominio | C19: Ordinario | D19: =-600*4 -> -2400 | E19: =$E$4 -> 44895 | F19: =EDATE(E19,$E$5*12)-1 -> 55486
B20: Assicurazione | C20: - | D20: =-23.7*12 -> -284.4 | E20: =$E$4 -> 44895 | F20: 46053
B21: Utenze | C21: Gas | D21: =-12*12 -> -144 | E21: =$E$4 -> 44895 | F21: =EDATE(E21,$E$5*12)-1 -> 55486
B22: Utenze | C22: Luce | D22: =-35*12 -> -420 | E22: =$E$4 -> 44895 | F22: =EDATE(E22,$E$5*12)-1 -> 55486
B23: Utenze | C23: Internet | D23: =-20.88*12 -> -250.56 | E23: =$E$4 -> 44895 | F23: =EDATE(E23,$E$5*12)-1 -> 55486
B24: Manutenzione ordinaria | C24: - | D24: -200 | E24: =$E$4 -> 44895 | F24: =EDATE(E24,$E$5*12)-1 -> 55486
B25: Manutenzione straordinaria | C25: - | D25: -300 | E25: =$E$4 -> 44895 | F25: =EDATE(E25,$E$5*12)-1 -> 55486
B27: Ammortamenti
B28: Anni | D28: 10
B30: Oneri finanziari
B31: Mutuo0 | C31: Importo | D31: 294000 | E31: 44895 | F31: 45657
B32: Mutuo0 | C32: Periodi | D32: 12
B33: Mutuo0 | C33: Anni | D33: 20
B34: Mutuo0 | C34: Decorrenza | D34: 44958
B35: Mutuo0 | C35: Commissioni | D35: 4
B36: Mutuo0 | C36: Tasso | D36: 0.032 | E36: 45536 | F36: 46539
B37: Mutuo1 | C37: Importo | D37: 208635.71 | E37: 45716 | F37: =EDATE(E37,$D$33*$D$32)-1 -> 53020
B38: Mutuo1 | C38: Periodi | D38: 12
B39: Mutuo1 | C39: Anni | D39: 20
B40: Mutuo1 | C40: Decorrenza | D40: 45716
B41: Mutuo1 | C41: Commissioni | D41: 2.75
B42: Mutuo1 | C42: Tasso | D42: 0.0272 | E42: =D40 -> 45716 | F42: =EDATE(E42,$D$33*12)-1 -> 53020
B44: Tasse
B45: Imposte | C45: Registro | D45: =-IF($E$7="SI",MAX(2%*$D$8*105%*120,1000),MAX(9%*$D$8*105%*120,1000)) -> -1355.9868 | E45: =$E$4 -> 44895 | F45: =EDATE(E45,$E$5*12)-1 -> 55486
...

Sheet Liberazione
B1: Dati generali
B2: Asset | D2: Liberazione
B3: Acquisto | C3: Valore immobile | D3: =-215000 -> -215000 | E3: 45036 | F3: =EDATE(E3,($E$5)*12)-1 -> 55262
B4: Data acquisto | E4: 45036 | F4: =EDATE(E4,($E$5)*12)-1 -> 55262 | I4: IRR | J4: =$L$295 -> 0.054560219
B5: Anni investimento | E5: 28 | I5: NPV | J5: =MAX(293:293) -> 26054.394
B6: Acquisto da? | E6: Privato/Imprese
B7: Prima casa? | E7: NO
B8: Rendita catastale | C8: - | D8: =568.1+47.41+13.74 -> 629.25 | E8: =$E$4 -> 45036 | F8: =EDATE(E8,$E$5*12)-1 -> 55262
B9: Rivalutazione | C9: - | D9: 0 | E9: =E4 -> 45036 | F9: 45291
B10: Rivalutazione | C10: - | D10: 0.008 | E10: =F9+1 -> 45292 | F10: =F4 -> 55262
B12: Ricavi
B13: Affitto | C13: Alloggio | D13: =(900*12*(1-21%)+1100) -> 9632 | E13: 45036 | F13: 45809
B14: Affitto | C14: Alloggio | D14: =(900*12*(1-21%)+1700) -> 10232 | E14: 45839 | F14: 55262
B15: Affitto | C15: Box | D15: =25*12+120*12*0.57-67-16 -> 1037.8 | E15: 45036 | F15: 55262
B16: Vendita | C16: Alloggio | D16: 240000 | E16: 46356 | F16: 46356
B17: Vendita | C17: Box | D17: 0 | E17: 46356 | F17: 46356
B19: Costi
B20: Avviamento | C20: - | D20: 0 | E20: =$E$4 -> 45036 | F20: =EDATE(E20,$E$5*12)-1 -> 55262
B21: Condominio | C21: Ordinario | D21: =-1700 -> -1700 | E21: =$E$4 -> 45036 | F21: =EDATE(E21,$E$5*12)-1 -> 55262
B22: Condominio | C22: Straordinario | D22: -2500 | E22: 46023 | F22: 46388
B23: Assicurazione | C23: - | D23: =(-39.21+23.7)*12 -> -186.12 | E23: =$E$4 -> 45036 | F23: 46053
B24: Utenze | C24: Gas | D24: 0 | E24: =$E$4 -> 45036 | F24: =EDATE(E24,$E$5*12)-1 -> 55262
B25: Utenze | C25: Luce | D25: 0 | E25: =$E$4 -> 45036 | F25: =EDATE(E25,$E$5*12)-1 -> 55262
B26: Utenze | C26: Internet | D26: 0 | E26: =$E$4 -> 45036 | F26: =EDATE(E26,$E$5*12)-1 -> 55262
B27: Manutenzione ordinaria | C27: - | D27: 0 | E27: =$E$4 -> 45036 | F27: =EDATE(E27,$E$5*12)-1 -> 55262
B28: Manutenzione straordinaria | C28: - | D28: -500 | E28: =$E$4 -> 45036 | F28: =EDATE(E28,$E$5*12)-1 -> 55262
B30: Ammortamenti
B31: Anni | D31: 10
B33: Oneri finanziari - Mutuo
B35: Tasse
B36: Imposte | C36: Registro | D36: =-IF($E$7="SI",MAX(2%*$D$8*105%*120,1000),MAX(9%*$D$8*105%*120,1000)) -> -7135.695 | E36: =$E$4 -> 45036 | F36: =EDATE(E36,$E$5*12)-1 -> 55262
B37: Imposte | C37: Ipotecaria | D37: =-IF($E$6="Privato/Imprese",50,200) -> -50 | E37: =$E$4 -> 45036 | F37: =EDATE(E37,$E$5*12)-1 -> 55262
B38: Imposte | C38: Catastale | D38: =-IF($E$6="Privato/Imprese",50,200) -> -50 | E38: =$E$4 -> 45036 | F38: =EDATE(E38,$E$5*12)-1 -> 55262
B39: Imposte | C39: IMU | D39: =IF($E$7="522,91SI",0,$D$8*1.05*160*1.06%) -> 1120.5684 | E39: =$E$4 -> 45036 | F39: =EDATE(E39,$E$5*12)-1 -> 55262
B40: Imposte | C40: TARI | D40: -80 | E40: =$E$4 -> 45036 | F40: =EDATE(E40,$E$5*12)-1 -> 55262
B42: Detrazioni
B43: Mutuo | C43: Cap detrazione | D43: =4000*$D$34/296000 -> 0 | E43: Ripartizione mutuo
B44: Mutuo | C44: % detrazione | D44: 0.19
B45: Intermediazione | C45: Cap detrazione | D45: 1000
B46: Intermediazione | C46: % detrazione | D46: 0.19
...

Sheet DiazBox
B1: Dati generali
B2: Asset | D2: DiazBox
B3: Acquisto | C3: Valore immobile | D3: -13000 | E3: =E4 -> 45036 | F3: =EDATE($E$4,$E$5*12)-1 -> 46131
B4: Data acquisto | E4: 45036 | F4: 46387 | I4: IRR | J4: =$L$295 -> 0.041383851
B5: Anni investimento | E5: 3 | I5: NPV | J5: =MAX(293:293) -> 1349.8132
B6: Acquisto da? | E6: Privato/Imprese
B7: Prima casa? | E7: NO
B8: Rendita catastale | C8: - | D8: 57.84 | E8: =$E$4 -> 45036 | F8: =EDATE($E$4,$E$5*12)-1 -> 46131
B9: Rivalutazione | C9: - | D9: 0 | E9: =$E$4 -> 45036 | F9: =EDATE($E$4,$E$5*12)-1 -> 46131
B11: Ricavi
B12: Affitto | C12: Box | D12: =30*12+115*12*0.57-99 -> 1047.6 | E12: =$E$4 -> 45036 | F12: =EDATE($E$4,$E$5*12)-1 -> 46131
B13: Vendita | C13: Box | D13: =-(D3+D18+D19)+1500 -> 18092.61 | E13: =EDATE($E$4,$E$5*12)-1 -> 46131 | F13: 46387
B14: Vendita | C14: Intermediazione | D14: 0 | E14: =EDATE($E$4,$E$5*12)-1 -> 46131 | F14: =EDATE($E$4,$E$5*12)-1 -> 46131 | H14: $D$3*(1+D10)^E5
B15: Vendita | C15: Plusvalenza | D15: =-(D13+(D3+D19))*0.26 -> -707.2 | E15: =EDATE($E$4,$E$5*12)-1 -> 46131 | F15: 46387
B17: Costi
B18: Avviamento | C18: Intermediazione | D18: -1220 | E18: =$E$4 -> 45036 | F18: =EDATE($E$4,$E$5*12)-1 -> 46131
B19: Avviamento | C19: Notaio | D19: -2372.61 | E19: =$E$4 -> 45036 | F19: =EDATE($E$4,$E$5*12)-1 -> 46131
B20: Condominio | C20: - | D20: -100 | E20: =$E$4 -> 45036 | F20: =EDATE($E$4,$E$5*12)-1 -> 46131
B21: Assicurazione | C21: - | D21: 0 | E21: =$E$4 -> 45036 | F21: =EDATE($E$4,$E$5*12)-1 -> 46131
B22: Utenze | C22: Gas | D22: 0 | E22: =$E$4 -> 45036 | F22: =EDATE($E$4,$E$5*12)-1 -> 46131
B23: Utenze | C23: Luce | D23: 0 | E23: =$E$4 -> 45036 | F23: =EDATE($E$4,$E$5*12)-1 -> 46131
B24: Manutenzione ordinaria | C24: - | D24: 0 | E24: =$E$4 -> 45036 | F24: =EDATE($E$4,$E$5*12)-1 -> 46131
B25: Manutenzione straordinaria | C25: - | D25: -25 | E25: =$E$4 -> 45036 | F25: =EDATE($E$4,$E$5*12)-1 -> 46131
B27: Ammortamenti
B28: Anni | D28: =SUMIFS(#REF!,#REF!,$B28) -> #REF!
B30: Oneri finanziari
B31: Mutuo | C31: Importo | D31: 0
B32: Mutuo | C32: Periodi | D32: 12
B33: Mutuo | C33: Anni | D33: 20
B34: Mutuo | C34: Decorrenza | D34: 44958
B35: Mutuo | C35: Commissioni | D35: 0
B36: Mutuo | C36: Tasso | D36: 0 | E36: 45658 | F36: 46539
B37: Mutuo | C37: Tasso | D37: 0 | E37: =EDATE(F36,1) -> 46569 | F37: 47270
B38: Mutuo | C38: Tasso | D38: 0 | E38: =EDATE(F37,1) -> 47300 | F38: =EDATE(E38,25*12) -> 56431
B39: Mutuo | C39: Rimborso | D39: 0 | E39: 45658 | F39: 45658
B44: Tasse
B45: Imposte | C45: Registro | D45: =-IF($E$7="SI",MAX(2%*$D$8*105%*120,1000),MAX(9%*$D$8*105%*120,1000)) -> -1000 | E45: =$E$4 -> 45036 | F45: =EDATE(E45,$E$5*12)-1 -> 46131
B46: Imposte | C46: Ipotecaria | D46: =-IF($E$6="Privato/Imprese",50,200) -> -50 | E46: =$E$4 -> 45036 | F46: =EDATE(E46,$E$5*12)-1 -> 46131
B47: Imposte | C47: Catastale | D47: =-IF($E$6="Privato/Imprese",50,200) -> -50 | E47: =$E$4 -> 45036 | F47: =EDATE(E47,$E$5*12)-1 -> 46131
B48: Imposte | C48: IMU | D48: =-IF($E$7="SI",0,$D$8*1.05*160*1.06%) -> -103.00147 | E48: =$E$4 -> 45036 | F48: =EDATE(E48,$E$5*12)-1 -> 46131
...

Sheet Flussi
E1: IRR: | F1: =XIRR(F4:F135,G4:G135) -> 0.075784829 | I1: Strambio | J1: D | K1: =SUMIFS($F:$F,$M:$M,J1,$A:$A,$I$1) -> -17633.732 | L1: =-K1/2-K2 -> -15.134 | N1: Moggio | O1: D | P1: =SUMIFS($F:$F,$M:$M,O1,$A:$A,$N$1) -> -27434.03 | Q1: =P2+P1 -> 22733.97
E2: SUBTOTALE: | F2: =SUBTOTAL(9,F4:F135) -> 0 | J2: C | K2: =SUMIFS($F:$F,$M:$M,J2,$A:$A,$I$1) -> 8832 | O2: C | P2: =SUMIFS($F:$F,$M:$M,O2,$A:$A,$N$1) -> 50168
A3: Immobile | B3: Esercizio | C3: Tipo | D3: Servizio | E3: Voce | F3: Importo | G3: Data | H3: Note | I3: ACT/FRC | J3: Da | K3: A | L3: Codice | M3: Conticini Carla
A4: DiazBox | B4: =YEAR(G4) -> 2023 | C4: Investimenti | D4: Acquisto | E4: Valore immobile | F4: -13000 | G4: 45036 | H4: 3k€ di anticipo sostenuto da papà | I4: ACT
A5: DiazBox | B5: =YEAR(G5) -> 2023 | C5: Costi | D5: Avviamento | E5: Notaio | F5: -2372.61 | G5: 45036 | H5: Notaio | I5: ACT
A6: DiazBox | B6: =YEAR(G6) -> 2023 | C6: Costi | D6: Avviamento | E6: Intermediazione | F6: -1220 | G6: 45036 | H6: Agenzia (Spesa sostenutà da papà) | I6: ACT
A7: DiazBox | B7: =YEAR(G7) -> 2026 | C7: Ricavi | D7: Vendita | E7: Plusvalenza | F7: =SUMIFS(INDIRECT("'"&$A7&"'!"&"$D:$D"),INDIRECT("'"&$A7&"'!"&"$B:$B"),$D7,INDIRECT("'"&$A7&"'!"&"$C:$C"),$E7,INDIRECT("'"&$A7&"'!"&"$E:$E"),"<="&$G7,INDIRECT("'"&$A7&"'!"&"$F:$F"),">="&$G7) -> -707.2 | G7: 46387 | I7: FRC
A8: DiazBox | B8: =YEAR(G8) -> 2026 | C8: Ricavi | D8: Affitto | E8: Box | F8: -110 | G8: 46239 | H8: Restituzione Caparra | I8: ACT
A9: DiazBox | B9: =YEAR(G9) -> 2024 | C9: Tasse | D9: Imposte | E9: IMU | F9: -103 | G9: 45433 | I9: ACT
A10: DiazBox | B10: =YEAR(G10) -> 2025 | C10: Tasse | D10: Imposte | E10: IMU | F10: -103 | G10: 45776 | H10: Anticipo e saldo | I10: ACT
A11: DiazBox | B11: =YEAR(G11) -> 2026 | C11: Ricavi | D11: Affitto | E11: Box | F11: -83 | G11: 46073 | H11: Registrazione contratto | I11: ACT
A12: DiazBox | B12: =YEAR(G12) -> 2023 | C12: Tasse | D12: Imposte | E12: IMU | F12: -68.67 | G12: 45087 | I12: ACT
A13: DiazBox | B13: =YEAR(G13) -> 2025 | C13: Costi | D13: Condominio | E13: - | F13: -57.95 | G13: 45979 | H13: 2° rata | I13: ACT
A14: DiazBox | B14: =YEAR(G14) -> 2025 | C14: Tasse | D14: Imposte | E14: TARI | F14: =-(21.46+22.38) -> -43.84 | G14: 45989 | H14: Anticipo e saldo | I14: ACT
A15: DiazBox | B15: =YEAR(G15) -> 2025 | C15: Costi | D15: Condominio | E15: - | F15: -42 | G15: 45940 | H15: 1° rata | I15: ACT
A16: DiazBox | B16: =YEAR(G16) -> 2026 | C16: Costi | D16: Condominio | E16: - | F16: -42 | G16: 46049 | H16: 3° rata | I16: ACT
A17: DiazBox | B17: =YEAR(G17) -> 2026 | C17: Costi | D17: Condominio | E17: - | F17: -42 | G17: 46146 | H17: 4° rata | I17: ACT
A18: DiazBox | B18: =YEAR(G18) -> 2026 | C18: Costi | D18: Condominio | E18: - | F18: -42 | G18: 46325 | H18: 1° rata | I18: FRC
A19: DiazBox | B19: =YEAR(G19) -> 2026 | C19: Costi | D19: Condominio | E19: - | F19: -42 | G19: 46356 | H19: 2° rata | I19: FRC
A20: DiazBox | B20: =YEAR(G20) -> 2024 | C20: Tasse | D20: Imposte | E20: TARI | F20: -20 | G20: 45433 | H20: Valore stimato | I20: ACT
A21: DiazBox | B21: =YEAR(G21) -> 2026 | C21: Tasse | D21: Imposte | E21: TARI | F21: -20 | G21: 46169 | H21: Valore stimato | I21: ACT
A22: DiazBox | B22: =YEAR(G22) -> 2026 | C22: Costi | D22: Manutenzione straordinaria | E22: - | F22: -18 | G22: 46059 | H22: Copia chiavi BOX | I22: ACT
A23: DiazBox | B23: =YEAR(G23) -> 2023 | C23: Ricavi | D23: Affitto | E23: Box | F23: 0 | G23: 45037 | I23: ACT
A24: DiazBox | B24: =YEAR(G24) -> 2023 | C24: Costi | D24: Condominio | E24: - | F24: 0 | G24: 45037 | H24: Quota pagata da papà | I24: ACT
A25: DiazBox | B25: =YEAR(G25) -> 2023 | C25: Costi | D25: Manutenzione straordinaria | E25: - | F25: 0 | G25: 45037 | I25: ACT
A26: DiazBox | B26: =YEAR(G26) -> 2023 | C26: Tasse | D26: Imposte | E26: TARI | F26: 0 | G26: 45087 | H26: Confermato storno in data 20/07/2025. Da pagare dal 2025 in poi. | I26: ACT
A27: DiazBox | B27: =YEAR(G27) -> 2024 | C27: Ricavi | D27: Affitto | E27: Box | F27: 0 | G27: 45292 | I27: ACT
A28: DiazBox | B28: =YEAR(G28) -> 2024 | C28: Costi | D28: Condominio | E28: - | F28: 0 | G28: 45292 | H28: Quota pagata da papà | I28: ACT
A29: DiazBox | B29: =YEAR(G29) -> 2024 | C29: Costi | D29: Manutenzione straordinaria | E29: - | F29: 0 | G29: 45292 | I29: ACT
A30: DiazBox | B30: =YEAR(G30) -> 2025 | C30: Costi | D30: Manutenzione straordinaria | E30: - | F30: 0 | G30: 45658 | I30: ACT
A31: DiazBox | B31: =YEAR(G31) -> 2026 | C31: Ricavi | D31: Affitto | E31: Box | F31: 0 | G31: 46240 | H31: Secondi 6 mesi | I31: FRC
A32: DiazBox | B32: =YEAR(G32) -> 2026 | C32: Ricavi | D32: Vendita | E32: Intermediazione | F32: 0 | G32: 46387 | I32: FRC
A33: DiazBox | B33: =YEAR(G33) -> 2026 | C33: Tasse | D33: Imposte | E33: IMU | F33: 51.5 | G33: 46148 | H33: Anticipo | I33: ACT
A34: DiazBox | B34: =YEAR(G34) -> 2026 | C34: Tasse | D34: Imposte | E34: IMU | F34: 51.5 | G34: 46357 | H34: Saldo | I34: FRC
A35: DiazBox | B35: =YEAR(G35) -> 2026 | C35: Ricavi | D35: Affitto | E35: Box | F35: 110 | G35: 46059 | H35: Caparra | I35: ACT
A36: DiazBox | B36: =YEAR(G36) -> 2026 | C36: Ricavi | D36: Affitto | E36: Box | F36: -300 | G36: 46059 | H36: tasse | I36: ACT
A37: DiazBox | B37: =YEAR(G37) -> 2026 | C37: Ricavi | D37: Affitto | E37: Box | F37: -110 | G37: 46059 | H37: RestituzioneCaparra | I37: ACT
A38: DiazBox | B38: =YEAR(G38) -> 2026 | C38: Ricavi | D38: Affitto | E38: Box | F38: 780 | G38: 46059 | H38: Primi 6 mesi | I38: ACT
A39: DiazBox | B39: =YEAR(G39) -> 2025 | C39: Ricavi | D39: Affitto | E39: Box | F39: =20*12+110*12*0.57-99 -> 893.4 | G39: 45658 | H39: Dal 8 dic 2024 | I39: ACT
A40: DiazBox | B40: =YEAR(G40) -> 2026 | C40: Ricavi | D40: Vendita | E40: Box | F40: =SUMIFS(INDIRECT("'"&$A40&"'!"&"$D:$D"),INDIRECT("'"&$A40&"'!"&"$B:$B"),$D40,INDIRECT("'"&$A40&"'!"&"$C:$C"),$E40,INDIRECT("'"&$A40&"'!"&"$E:$E"),"<="&$G40,INDIRECT("'"&$A40&"'!"&"$F:$F"),">="&$G40) -> 18092.61 | G40: 46387 | I40: FRC
...

Sheet StrambioMutuo0
G7: =SUBTOTAL(9,$G9:$G486) -> 23862.34 | H7: =SUBTOTAL(9,$H9:$H486) -> 16154.97 | I7: =SUBTOTAL(9,$I9:$I486) -> 278635.71 | J7: =SUBTOTAL(9,$J9:$J486) -> 294790.68 | K7: =SUBTOTAL(5,$K9:$K486) -> -790.68 | O7: =SUBTOTAL(9,$O9:$O486) -> 96
A8: Esercizio | B8: Annualità | C8: Periodo | D8: Scadenza | E8: Tasso annuale | F8: Rata netta | G8: Interessi | H8: Capitale | I8: Rimborsi anticipati | J8: Capitale restituito | K8: Importo residuo | L8: Preammortamento/ Interessi accessori | M8: Quota interessi | N8: Cumulato oneri finaziari | O8: Spese pagamento | P8: Rata lorda
C9: 0 | K9: =Strambio!$D$31 -> 294000
A10: =YEAR(D10) -> 2023 | B10: =_xlfn.FLOOR.MATH(($C10-1)/12)+1 -> 1 | C10: =C9+1 -> 1 | D10: =EDATE(Strambio!$D$34,$C10-1) -> 44958 | E10: 0.0325 | F10: 2079.64 | G10: 1204.33 | H10: =IF($C10<=Strambio!$D$32*Strambio!$D$33,$F10-$G10-O10,0) -> 871.31 | I10: 0 | J10: =IF($C10<=Strambio!$D$32*Strambio!$D$33,H10+I10,0) -> 871.31 | K10: =IF($C10<=Strambio!$D$32*Strambio!$D$33,($K9-$H10-$I10),0) -> 293128.69 | L10: 0 | M10: =IF($C10<=Strambio!$D$32*Strambio!$D$33,$G10+$L10,0) -> 1204.33 | N10: =IF($C10<=Strambio!$D$32*Strambio!$D$33,$N9+L10+$G10,0) -> 1204.33 | O10: =IF(F10=0,0,IF($C10<=Strambio!$D$32*Strambio!$D$33,Strambio!$D$35,0)) -> 4 | P10: =IF($C10<=Strambio!$D$32*Strambio!$D$33,($F10+$L10+O$10),0) -> 2083.64
A11: =YEAR(D11) -> 2023 | B11: =_xlfn.FLOOR.MATH(($C11-1)/12)+1 -> 1 | C11: =C10+1 -> 2 | D11: =EDATE(Strambio!$D$34,$C11-1) -> 44986 | E11: 0.0345 | F11: 1645.24 | G11: 786.56 | H11: =IF($C11<=Strambio!$D$32*Strambio!$D$33,$F11-$G11-O11,0) -> 854.68 | I11: 0 | J11: =IF($C11<=Strambio!$D$32*Strambio!$D$33,H11+I11,0) -> 854.68 | K11: =IF($C11<=Strambio!$D$32*Strambio!$D$33,($K10-$H11-$I11),0) -> 292274.01 | L11: 0 | M11: =IF($C11<=Strambio!$D$32*Strambio!$D$33,$G11+$L11,0) -> 786.56 | N11: =IF($C11<=Strambio!$D$32*Strambio!$D$33,$N10+L11+$G11,0) -> 1990.89 | O11: =IF(F11=0,0,IF($C11<=Strambio!$D$32*Strambio!$D$33,Strambio!$D$35,0)) -> 4 | P11: =IF($C11<=Strambio!$D$32*Strambio!$D$33,($F11+$L11+O$10),0) -> 1649.24
A12: =YEAR(D12) -> 2023 | B12: =_xlfn.FLOOR.MATH(($C12-1)/12)+1 -> 1 | C12: =C11+1 -> 3 | D12: =EDATE(Strambio!$D$34,$C12-1) -> 45017 | E12: 0.0375 | F12: 1777.09 | G12: 943.8 | H12: =IF($C12<=Strambio!$D$32*Strambio!$D$33,$F12-$G12-O12,0) -> 829.29 | I12: 0 | J12: =IF($C12<=Strambio!$D$32*Strambio!$D$33,H12+I12,0) -> 829.29 | K12: =IF($C12<=Strambio!$D$32*Strambio!$D$33,($K11-$H12-$I12),0) -> 291444.72 | L12: 0 | M12: =IF($C12<=Strambio!$D$32*Strambio!$D$33,$G12+$L12,0) -> 943.8 | N12: =IF($C12<=Strambio!$D$32*Strambio!$D$33,$N11+L12+$G12,0) -> 2934.69 | O12: =IF(F12=0,0,IF($C12<=Strambio!$D$32*Strambio!$D$33,Strambio!$D$35,0)) -> 4 | P12: =IF($C12<=Strambio!$D$32*Strambio!$D$33,($F12+$L12+O$10),0) -> 1781.09
A13: =YEAR(D13) -> 2023 | B13: =_xlfn.FLOOR.MATH(($C13-1)/12)+1 -> 1 | C13: =C12+1 -> 4 | D13: =EDATE(Strambio!$D$34,$C13-1) -> 45047 | E13: 0.0425 | F13: 1823.24 | G13: 1032.2 | H13: =IF($C13<=Strambio!$D$32*Strambio!$D$33,$F13-$G13-O13,0) -> 787.04 | I13: 0 | J13: =IF($C13<=Strambio!$D$32*Strambio!$D$33,H13+I13,0) -> 787.04 | K13: =IF($C13<=Strambio!$D$32*Strambio!$D$33,($K12-$H13-$I13),0) -> 290657.68 | L13: 0 | M13: =IF($C13<=Strambio!$D$32*Strambio!$D$33,$G13+$L13,0) -> 1032.2 | N13: =IF($C13<=Strambio!$D$32*Strambio!$D$33,$N12+L13+$G13,0) -> 3966.89 | O13: =IF(F13=0,0,IF($C13<=Strambio!$D$32*Strambio!$D$33,Strambio!$D$35,0)) -> 4 | P13: =IF($C13<=Strambio!$D$32*Strambio!$D$33,($F13+$L13+O$10),0) -> 1827.24
A14: =YEAR(D14) -> 2023 | B14: =_xlfn.FLOOR.MATH(($C14-1)/12)+1 -> 1 | C14: =C13+1 -> 5 | D14: =EDATE(Strambio!$D$34,$C14-1) -> 45078 | E14: 0.0435 | F14: 1777.36 | G14: 1032.57 | H14: =IF($C14<=Strambio!$D$32*Strambio!$D$33,$F14-$G14-O14,0) -> 740.79 | I14: 15000 | J14: =IF($C14<=Strambio!$D$32*Strambio!$D$33,H14+I14,0) -> 15740.79 | K14: =IF($C14<=Strambio!$D$32*Strambio!$D$33,($K13-$H14-$I14),0) -> 274916.89 | L14: 0 | M14: =IF($C14<=Strambio!$D$32*Strambio!$D$33,$G14+$L14,0) -> 1032.57 | N14: =IF($C14<=Strambio!$D$32*Strambio!$D$33,$N13+L14+$G14,0) -> 4999.46 | O14: =IF(F14=0,0,IF($C14<=Strambio!$D$32*Strambio!$D$33,Strambio!$D$35,0)) -> 4 | P14: =IF($C14<=Strambio!$D$32*Strambio!$D$33,($F14+$L14+O$10),0) -> 1781.36
A15: =YEAR(D15) -> 2023 | B15: =_xlfn.FLOOR.MATH(($C15-1)/12)+1 -> 1 | C15: =C14+1 -> 6 | D15: =EDATE(Strambio!$D$34,$C15-1) -> 45108 | E15: 0.0455 | F15: 1773.52 | G15: 1042.39 | H15: =IF($C15<=Strambio!$D$32*Strambio!$D$33,$F15-$G15-O15,0) -> 727.13 | I15: 0 | J15: =IF($C15<=Strambio!$D$32*Strambio!$D$33,H15+I15,0) -> 727.13 | K15: =IF($C15<=Strambio!$D$32*Strambio!$D$33,($K14-$H15-$I15),0) -> 274189.76 | L15: 0 | M15: =IF($C15<=Strambio!$D$32*Strambio!$D$33,$G15+$L15,0) -> 1042.39 | N15: =IF($C15<=Strambio!$D$32*Strambio!$D$33,$N14+L15+$G15,0) -> 6041.85 | O15: =IF(F15=0,0,IF($C15<=Strambio!$D$32*Strambio!$D$33,Strambio!$D$35,0)) -> 4 | P15: =IF($C15<=Strambio!$D$32*Strambio!$D$33,($F15+$L15+O$10),0) -> 1777.52
A16: =YEAR(D16) -> 2023 | B16: =_xlfn.FLOOR.MATH(($C16-1)/12)+1 -> 1 | C16: =C15+1 -> 7 | D16: =EDATE(Strambio!$D$34,$C16-1) -> 45139 | E16: 0.0475 | F16: 1839.35 | G16: 1121.51 | H16: =IF($C16<=Strambio!$D$32*Strambio!$D$33,$F16-$G16-O16,0) -> 713.84 | I16: 0 | J16: =IF($C16<=Strambio!$D$32*Strambio!$D$33,H16+I16,0) -> 713.84 | K16: =IF($C16<=Strambio!$D$32*Strambio!$D$33,($K15-$H16-$I16),0) -> 273475.92 | L16: 0 | M16: =IF($C16<=Strambio!$D$32*Strambio!$D$33,$G16+$L16,0) -> 1121.51 | N16: =IF($C16<=Strambio!$D$32*Strambio!$D$33,$N15+L16+$G16,0) -> 7163.36 | O16: =IF(F16=0,0,IF($C16<=Strambio!$D$32*Strambio!$D$33,Strambio!$D$35,0)) -> 4 | P16: =IF($C16<=Strambio!$D$32*Strambio!$D$33,($F16+$L16+O$10),0) -> 1843.35
A17: =YEAR(D17) -> 2023 | B17: =_xlfn.FLOOR.MATH(($C17-1)/12)+1 -> 1 | C17: =C16+1 -> 8 | D17: =EDATE(Strambio!$D$34,$C17-1) -> 45170 | E17: 0.049 | F17: 1862.74 | G17: 1153.92 | H17: =IF($C17<=Strambio!$D$32*Strambio!$D$33,$F17-$G17-O17,0) -> 704.82 | I17: 0 | J17: =IF($C17<=Strambio!$D$32*Strambio!$D$33,H17+I17,0) -> 704.82 | K17: =IF($C17<=Strambio!$D$32*Strambio!$D$33,($K16-$H17-$I17),0) -> 272771.1 | L17: 0 | M17: =IF($C17<=Strambio!$D$32*Strambio!$D$33,$G17+$L17,0) -> 1153.92 | N17: =IF($C17<=Strambio!$D$32*Strambio!$D$33,$N16+L17+$G17,0) -> 8317.28 | O17: =IF(F17=0,0,IF($C17<=Strambio!$D$32*Strambio!$D$33,Strambio!$D$35,0)) -> 4 | P17: =IF($C17<=Strambio!$D$32*Strambio!$D$33,($F17+$L17+O$10),0) -> 1866.74
A18: =YEAR(D18) -> 2023 | B18: =_xlfn.FLOOR.MATH(($C18-1)/12)+1 -> 1 | C18: =C17+1 -> 9 | D18: =EDATE(Strambio!$D$34,$C18-1) -> 45200 | E18: 0.05 | F18: 1840.44 | G18: 1136.55 | H18: =IF($C18<=Strambio!$D$32*Strambio!$D$33,$F18-$G18-O18,0) -> 699.89 | I18: 0 | J18: =IF($C18<=Strambio!$D$32*Strambio!$D$33,H18+I18,0) -> 699.89 | K18: =IF($C18<=Strambio!$D$32*Strambio!$D$33,($K17-$H18-$I18),0) -> 272071.21 | L18: 0 | M18: =IF($C18<=Strambio!$D$32*Strambio!$D$33,$G18+$L18,0) -> 1136.55 | N18: =IF($C18<=Strambio!$D$32*Strambio!$D$33,$N17+L18+$G18,0) -> 9453.83 | O18: =IF(F18=0,0,IF($C18<=Strambio!$D$32*Strambio!$D$33,Strambio!$D$35,0)) -> 4 | P18: =IF($C18<=Strambio!$D$32*Strambio!$D$33,($F18+$L18+O$10),0) -> 1844.44
A19: =YEAR(D19) -> 2023 | B19: =_xlfn.FLOOR.MATH(($C19-1)/12)+1 -> 1 | C19: =C18+1 -> 10 | D19: =EDATE(Strambio!$D$34,$C19-1) -> 45231 | E19: 0.0515 | F19: 1901.79 | G19: 1206.56 | H19: =IF($C19<=Strambio!$D$32*Strambio!$D$33,$F19-$G19-O19,0) -> 691.23 | I19: 0 | J19: =IF($C19<=Strambio!$D$32*Strambio!$D$33,H19+I19,0) -> 691.23 | K19: =IF($C19<=Strambio!$D$32*Strambio!$D$33,($K18-$H19-$I19),0) -> 271379.98 | L19: 0 | M19: =IF($C19<=Strambio!$D$32*Strambio!$D$33,$G19+$L19,0) -> 1206.56 | N19: =IF($C19<=Strambio!$D$32*Strambio!$D$33,$N18+L19+$G19,0) -> 10660.39 | O19: =IF(F19=0,0,IF($C19<=Strambio!$D$32*Strambio!$D$33,Strambio!$D$35,0)) -> 4 | P19: =IF($C19<=Strambio!$D$32*Strambio!$D$33,($F19+$L19+O$10),0) -> 1905.79
A20: =YEAR(D20) -> 2023 | B20: =_xlfn.FLOOR.MATH(($C20-1)/12)+1 -> 1 | C20: =C19+1 -> 11 | D20: =EDATE(Strambio!$D$34,$C20-1) -> 45261 | E20: 0.052 | F20: 1767.19 | G20: 1110.98 | H20: =IF($C20<=Strambio!$D$32*Strambio!$D$33,$F20-$G20-O20,0) -> 652.21 | I20: 15000 | J20: =IF($C20<=Strambio!$D$32*Strambio!$D$33,H20+I20,0) -> 15652.21 | K20: =IF($C20<=Strambio!$D$32*Strambio!$D$33,($K19-$H20-$I20),0) -> 255727.77 | L20: 0 | M20: =IF($C20<=Strambio!$D$32*Strambio!$D$33,$G20+$L20,0) -> 1110.98 | N20: =IF($C20<=Strambio!$D$32*Strambio!$D$33,$N19+L20+$G20,0) -> 11771.37 | O20: =IF(F20=0,0,IF($C20<=Strambio!$D$32*Strambio!$D$33,Strambio!$D$35,0)) -> 4 | P20: =IF($C20<=Strambio!$D$32*Strambio!$D$33,($F20+$L20+O$10),0) -> 1771.19
A21: =YEAR(D21) -> 2024 | B21: =_xlfn.FLOOR.MATH(($C21-1)/12)+1 -> 1 | C21: =C20+1 -> 12 | D21: =EDATE(Strambio!$D$34,$C21-1) -> 45292 | E21: 0.052 | F21: 1804.13 | G21: 1145.09 | H21: =IF($C21<=Strambio!$D$32*Strambio!$D$33,$F21-$G21-O21,0) -> 655.04 | I21: 0 | J21: =IF($C21<=Strambio!$D$32*Strambio!$D$33,H21+I21,0) -> 655.04 | K21: =IF($C21<=Strambio!$D$32*Strambio!$D$33,($K20-$H21-$I21),0) -> 255072.73 | L21: 0 | M21: =IF($C21<=Strambio!$D$32*Strambio!$D$33,$G21+$L21,0) -> 1145.09 | N21: =IF($C21<=Strambio!$D$32*Strambio!$D$33,$N20+L21+$G21,0) -> 12916.46 | O21: =IF(F21=0,0,IF($C21<=Strambio!$D$32*Strambio!$D$33,Strambio!$D$35,0)) -> 4 | P21: =IF($C21<=Strambio!$D$32*Strambio!$D$33,($F21+$L21+O$10),0) -> 1808.13
... A33: =YEAR(D33) -> 2025 | B33: =_xlfn.FLOOR.MATH(($C33-1)/12)+1 -> 2 | C33: =C32+1 -> 24 | D33: =EDATE(Strambio!$D$34,$C33-1) -> 45658 | E33: 0.047 | F33: 1481.91 | G33: 781.16 | H33: =IF($C33<=Strambio!$D$32*Strambio!$D$33,$F33-$G33-O33,0) -> 696.75 | I33: 208635.71 | J33: =IF($C33<=Strambio!$D$32*Strambio!$D$33,H33+I33,0) -> 209332.46 | K33: =IF($C33<=Strambio!$D$32*Strambio!$D$33,($K32-$H33-$I33),0) -> -790.68 | L33: 0 | M33: =IF($C33<=Strambio!$D$32*Strambio!$D$33,$G33+$L33,0) -> 781.16 | N33: =IF($C33<=Strambio!$D$32*Strambio!$D$33,$N32+L33+$G33,0) -> 23862.34 | O33: =IF(F33=0,0,IF($C33<=Strambio!$D$32*Strambio!$D$33,Strambio!$D$35,0)) -> 4 | P33: =IF($C33<=Strambio!$D$32*Strambio!$D$33,($F33+$L33+O$10),0) -> 1485.91

Sheet StrambioMutuo1
D4: 0.32863266
D5: 67697.869
G6: =G7/J7 -> 0.29764595
G7: =SUBTOTAL(9,$G9:$G762) -> 62099.575 | H7: =SUBTOTAL(9,$H9:$H762) -> 208635.71 | I7: =SUBTOTAL(9,$I9:$I762) -> 0 | J7: =SUBTOTAL(9,$J9:$J762) -> 208635.71 | K7: =SUBTOTAL(5,$K9:$K762) -> -2.2737368e-13 | O7: =SUBTOTAL(9,$O9:$O762) -> 660
A8: Esercizio | B8: Annualità | C8: Periodo | D8: Scadenza | E8: Tasso annuale | F8: Rata netta | G8: Interessi | H8: Capitale | I8: Rimborsi anticipati | J8: Capitale restituito | K8: Importo residuo | L8: Preammortamento/ Interessi accessori | M8: Quota interessi | N8: Cumulato oneri finaziari | O8: Spese pagamento | P8: Rata lorda
C9: 0 | K9: =Strambio!$D$37 -> 208635.71
A10: =YEAR(D10) -> 2025 | B10: =_xlfn.FLOOR.MATH(($C10-1)/12)+1 -> 1 | C10: =C9+1 -> 1 | D10: =EDATE(Strambio!$D$40,$C10-1) -> 45716 | E10: =SUMIFS(Strambio!$D:$D,Strambio!$B:$B,"Mutuo1",Strambio!$C:$C,"Tasso",Strambio!$E:$E,"<="&$D10,Strambio!$F:$F,">="&$D10) -> 0.0272 | F10: =IF($C10<=Strambio!$D$38*Strambio!$D$39,PMT($E10/Strambio!$D$38,Strambio!$D$38*Strambio!$D$39-$C9,-$K9),0) -> 1128.0637 | G10: =IF($C10<=Strambio!$D$38*Strambio!$D$39,$K9*$E10/Strambio!$D$38,0) -> 472.90761 | H10: =IF($C10<=Strambio!$D$38*Strambio!$D$39,$F10-$G10,0) -> 655.15608 | I10: =SUMIFS(Strambio!$D:$D,Strambio!$B:$B,"Mutuo1",Strambio!$C:$C,"Rimborso",Strambio!$E:$E,"<="&$D10,Strambio!$F:$F,">="&$D10) -> 0 | J10: =IF($C10<=Strambio!$D$38*Strambio!$D$39,H10+I10,0) -> 655.15608 | K10: =IF($C10<=Strambio!$D$38*Strambio!$D$39,($K9-$H10-$I10),0) -> 207980.55 | L10: 0 | M10: =IF($C10<=Strambio!$D$38*Strambio!$D$39,$G10+$L10,0) -> 472.90761 | N10: =IF($C10<=Strambio!$D$38*Strambio!$D$39,$N9+L10+$G10,0) -> 472.90761 | O10: =IF($C10<=Strambio!$D$38*Strambio!$D$39,Strambio!$D$41,0) -> 2.75 | P10: =IF($C10<=Strambio!$D$38*Strambio!$D$39,($F10+$L10+O$10),0) -> 1130.8137
A11: =YEAR(D11) -> 2025 | B11: =_xlfn.FLOOR.MATH(($C11-1)/12)+1 -> 1 | C11: =C10+1 -> 2 | D11: =EDATE(Strambio!$D$40,$C11-1) -> 45744 | E11: =SUMIFS(Strambio!$D:$D,Strambio!$B:$B,"Mutuo1",Strambio!$C:$C,"Tasso",Strambio!$E:$E,"<="&$D11,Strambio!$F:$F,">="&$D11) -> 0.0272 | F11: =IF($C11<=Strambio!$D$38*Strambio!$D$39,PMT($E11/Strambio!$D$38,Strambio!$D$38*Strambio!$D$39-$C10,-$K10),0) -> 1128.0637 | G11: =IF($C11<=Strambio!$D$38*Strambio!$D$39,$K10*$E11/Strambio!$D$38,0) -> 471.42259 | H11: =IF($C11<=Strambio!$D$38*Strambio!$D$39,$F11-$G11,0) -> 656.6411 | I11: =SUMIFS(Strambio!$D:$D,Strambio!$B:$B,"Mutuo1",Strambio!$C:$C,"Rimborso",Strambio!$E:$E,"<="&$D11,Strambio!$F:$F,">="&$D11) -> 0 | J11: =IF($C11<=Strambio!$D$38*Strambio!$D$39,H11+I11,0) -> 656.6411 | K11: =IF($C11<=Strambio!$D$38*Strambio!$D$39,($K10-$H11-$I11),0) -> 207323.91 | L11: 0 | M11: =IF($C11<=Strambio!$D$38*Strambio!$D$39,$G11+$L11,0) -> 471.42259 | N11: =IF($C11<=Strambio!$D$38*Strambio!$D$39,$N10+L11+$G11,0) -> 944.3302 | O11: =IF($C11<=Strambio!$D$38*Strambio!$D$39,Strambio!$D$41,0) -> 2.75 | P11: =IF($C11<=Strambio!$D$38*Strambio!$D$39,($F11+$L11+O$10),0) -> 1130.8137
A12: =YEAR(D12) -> 2025 | B12: =_xlfn.FLOOR.MATH(($C12-1)/12)+1 -> 1 | C12: =C11+1 -> 3 | D12: =EDATE(Strambio!$D$40,$C12-1) -> 45775 | E12: =SUMIFS(Strambio!$D:$D,Strambio!$B:$B,"Mutuo1",Strambio!$C:$C,"Tasso",Strambio!$E:$E,"<="&$D12,Strambio!$F:$F,">="&$D12) -> 0.0272 | F12: =IF($C12<=Strambio!$D$38*Strambio!$D$39,PMT($E12/Strambio!$D$38,Strambio!$D$38*Strambio!$D$39-$C11,-$K11),0) -> 1128.0637 | G12: =IF($C12<=Strambio!$D$38*Strambio!$D$39,$K11*$E12/Strambio!$D$38,0) -> 469.9342 | H12: =IF($C12<=Strambio!$D$38*Strambio!$D$39,$F12-$G12,0) -> 658.12948 | I12: =SUMIFS(Strambio!$D:$D,Strambio!$B:$B,"Mutuo1",Strambio!$C:$C,"Rimborso",Strambio!$E:$E,"<="&$D12,Strambio!$F:$F,">="&$D12) -> 0 | J12: =IF($C12<=Strambio!$D$38*Strambio!$D$39,H12+I12,0) -> 658.12948 | K12: =IF($C12<=Strambio!$D$38*Strambio!$D$39,($K11-$H12-$I12),0) -> 206665.78 | L12: 0 | M12: =IF($C12<=Strambio!$D$38*Strambio!$D$39,$G12+$L12,0) -> 469.9342 | N12: =IF($C12<=Strambio!$D$38*Strambio!$D$39,$N11+L12+$G12,0) -> 1414.2644 | O12: =IF($C12<=Strambio!$D$38*Strambio!$D$39,Strambio!$D$41,0) -> 2.75 | P12: =IF($C12<=Strambio!$D$38*Strambio!$D$39,($F12+$L12+O$10),0) -> 1130.8137
A13: =YEAR(D13) -> 2025 | B13: =_xlfn.FLOOR.MATH(($C13-1)/12)+1 -> 1 | C13: =C12+1 -> 4 | D13: =EDATE(Strambio!$D$40,$C13-1) -> 45805 | E13: =SUMIFS(Strambio!$D:$D,Strambio!$B:$B,"Mutuo1",Strambio!$C:$C,"Tasso",Strambio!$E:$E,"<="&$D13,Strambio!$F:$F,">="&$D13) -> 0.0272 | F13: =IF($C13<=Strambio!$D$38*Strambio!$D$39,PMT($E13/Strambio!$D$38,Strambio!$D$38*Strambio!$D$39-$C12,-$K12),0) -> 1128.0637 | G13: =IF($C13<=Strambio!$D$38*Strambio!$D$39,$K12*$E13/Strambio!$D$38,0) -> 468.44244 | H13: =IF($C13<=Strambio!$D$38*Strambio!$D$39,$F13-$G13,0) -> 659.62124 | I13: =SUMIFS(Strambio!$D:$D,Strambio!$B:$B,"Mutuo1",Strambio!$C:$C,"Rimborso",Strambio!$E:$E,"<="&$D13,Strambio!$F:$F,">="&$D13) -> 0 | J13: =IF($C13<=Strambio!$D$38*Strambio!$D$39,H13+I13,0) -> 659.62124 | K13: =IF($C13<=Strambio!$D$38*Strambio!$D$39,($K12-$H13-$I13),0) -> 206006.16 | L13: 0 | M13: =IF($C13<=Strambio!$D$38*Strambio!$D$39,$G13+$L13,0) -> 468.44244 | N13: =IF($C13<=Strambio!$D$38*Strambio!$D$39,$N12+L13+$G13,0) -> 1882.7068 | O13: =IF($C13<=Strambio!$D$38*Strambio!$D$39,Strambio!$D$41,0) -> 2.75 | P13: =IF($C13<=Strambio!$D$38*Strambio!$D$39,($F13+$L13+O$10),0) -> 1130.8137
A14: =YEAR(D14) -> 2025 | B14: =_xlfn.FLOOR.MATH(($C14-1)/12)+1 -> 1 | C14: =C13+1 -> 5 | D14: =EDATE(Strambio!$D$40,$C14-1) -> 45836 | E14: =SUMIFS(Strambio!$D:$D,Strambio!$B:$B,"Mutuo1",Strambio!$C:$C,"Tasso",Strambio!$E:$E,"<="&$D14,Strambio!$F:$F,">="&$D14) -> 0.0272 | F14: =IF($C14<=Strambio!$D$38*Strambio!$D$39,PMT($E14/Strambio!$D$38,Strambio!$D$38*Strambio!$D$39-$C13,-$K13),0) -> 1128.0637 | G14: =IF($C14<=Strambio!$D$38*Strambio!$D$39,$K13*$E14/Strambio!$D$38,0) -> 466.9473 | H14: =IF($C14<=Strambio!$D$38*Strambio!$D$39,$F14-$G14,0) -> 661.11639 | I14: =SUMIFS(Strambio!$D:$D,Strambio!$B:$B,"Mutuo1",Strambio!$C:$C,"Rimborso",Strambio!$E:$E,"<="&$D14,Strambio!$F:$F,">="&$D14) -> 0 | J14: =IF($C14<=Strambio!$D$38*Strambio!$D$39,H14+I14,0) -> 661.11639 | K14: =IF($C14<=Strambio!$D$38*Strambio!$D$39,($K13-$H14-$I14),0) -> 205345.05 | L14: 0 | M14: =IF($C14<=Strambio!$D$38*Strambio!$D$39,$G14+$L14,0) -> 466.9473 | N14: =IF($C14<=Strambio!$D$38*Strambio!$D$39,$N13+L14+$G14,0) -> 2349.6541 | O14: =IF($C14<=Strambio!$D$38*Strambio!$D$39,Strambio!$D$41,0) -> 2.75 | P14: =IF($C14<=Strambio!$D$38*Strambio!$D$39,($F14+$L14+O$10),0) -> 1130.8137
A15: =YEAR(D15) -> 2025 | B15: =_xlfn.FLOOR.MATH(($C15-1)/12)+1 -> 1 | C15: =C14+1 -> 6 | D15: =EDATE(Strambio!$D$40,$C15-1) -> 45866 | E15: =SUMIFS(Strambio!$D:$D,Strambio!$B:$B,"Mutuo1",Strambio!$C:$C,"Tasso",Strambio!$E:$E,"<="&$D15,Strambio!$F:$F,">="&$D15) -> 0.0272 | F15: =IF($C15<=Strambio!$D$38*Strambio!$D$39,PMT($E15/Strambio!$D$38,Strambio!$D$38*Strambio!$D$39-$C14,-$K14),0) -> 1128.0637 | G15: =IF($C15<=Strambio!$D$38*Strambio!$D$39,$K14*$E15/Strambio!$D$38,0) -> 465.44877 | H15: =IF($C15<=Strambio!$D$38*Strambio!$D$39,$F15-$G15,0) -> 662.61492 | I15: =SUMIFS(Strambio!$D:$D,Strambio!$B:$B,"Mutuo1",Strambio!$C:$C,"Rimborso",Strambio!$E:$E,"<="&$D15,Strambio!$F:$F,">="&$D15) -> 0 | J15: =IF($C15<=Strambio!$D$38*Strambio!$D$39,H15+I15,0) -> 662.61492 | K15: =IF($C15<=Strambio!$D$38*Strambio!$D$39,($K14-$H15-$I15),0) -> 204682.43 | L15: 0 | M15: =IF($C15<=Strambio!$D$38*Strambio!$D$39,$G15+$L15,0) -> 465.44877 | N15: =IF($C15<=Strambio!$D$38*Strambio!$D$39,$N14+L15+$G15,0) -> 2815.1029 | O15: =IF($C15<=Strambio!$D$38*Strambio!$D$39,Strambio!$D$41,0) -> 2.75 | P15: =IF($C15<=Strambio!$D$38*Strambio!$D$39,($F15+$L15+O$10),0) -> 1130.8137
A16: =YEAR(D16) -> 2025 | B16: =_xlfn.FLOOR.MATH(($C16-1)/12)+1 -> 1 | C16: =C15+1 -> 7 | D16: =EDATE(Strambio!$D$40,$C16-1) -> 45897 | E16: =SUMIFS(Strambio!$D:$D,Strambio!$B:$B,"Mutuo1",Strambio!$C:$C,"Tasso",Strambio!$E:$E,"<="&$D16,Strambio!$F:$F,">="&$D16) -> 0.0272 | F16: =IF($C16<=Strambio!$D$38*Strambio!$D$39,PMT($E16/Strambio!$D$38,Strambio!$D$38*Strambio!$D$39-$C15,-$K15),0) -> 1128.0637 | G16: =IF($C16<=Strambio!$D$38*Strambio!$D$39,$K15*$E16/Strambio!$D$38,0) -> 463.94684 | H16: =IF($C16<=Strambio!$D$38*Strambio!$D$39,$F16-$G16,0) -> 664.11684 | I16: =SUMIFS(Strambio!$D:$D,Strambio!$B:$B,"Mutuo1",Strambio!$C:$C,"Rimborso",Strambio!$E:$E,"<="&$D16,Strambio!$F:$F,">="&$D16) -> 0 | J16: =IF($C16<=Strambio!$D$38*Strambio!$D$39,H16+I16,0) -> 664.11684 | K16: =IF($C16<=Strambio!$D$38*Strambio!$D$39,($K15-$H16-$I16),0) -> 204018.31 | L16: 0 | M16: =IF($C16<=Strambio!$D$38*Strambio!$D$39,$G16+$L16,0) -> 463.94684 | N16: =IF($C16<=Strambio!$D$38*Strambio!$D$39,$N15+L16+$G16,0) -> 3279.0498 | O16: =IF($C16<=Strambio!$D$38*Strambio!$D$39,Strambio!$D$41,0) -> 2.75 | P16: =IF($C16<=Strambio!$D$38*Strambio!$D$39,($F16+$L16+O$10),0) -> 1130.8137
A17: =YEAR(D17) -> 2025 | B17: =_xlfn.FLOOR.MATH(($C17-1)/12)+1 -> 1 | C17: =C16+1 -> 8 | D17: =EDATE(Strambio!$D$40,$C17-1) -> 45928 | E17: =SUMIFS(Strambio!$D:$D,Strambio!$B:$B,"Mutuo1",Strambio!$C:$C,"Tasso",Strambio!$E:$E,"<="&$D17,Strambio!$F:$F,">="&$D17) -> 0.0272 | F17: =IF($C17<=Strambio!$D$38*Strambio!$D$39,PMT($E17/Strambio!$D$38,Strambio!$D$38*Strambio!$D$39-$C16,-$K16),0) -> 1128.0637 | G17: =IF($C17<=Strambio!$D$38*Strambio!$D$39,$K16*$E17/Strambio!$D$38,0) -> 462.44151 | H17: =IF($C17<=Strambio!$D$38*Strambio!$D$39,$F17-$G17,0) -> 665.62218 | I17: =SUMIFS(Strambio!$D:$D,Strambio!$B:$B,"Mutuo1",Strambio!$C:$C,"Rimborso",Strambio!$E:$E,"<="&$D17,Strambio!$F:$F,">="&$D17) -> 0 | J17: =IF($C17<=Strambio!$D$38*Strambio!$D$39,H17+I17,0) -> 665.62218 | K17: =IF($C17<=Strambio!$D$38*Strambio!$D$39,($K16-$H17-$I17),0) -> 203352.69 | L17: 0 | M17: =IF($C17<=Strambio!$D$38*Strambio!$D$39,$G17+$L17,0) -> 462.44151 | N17: =IF($C17<=Strambio!$D$38*Strambio!$D$39,$N16+L17+$G17,0) -> 3741.4913 | O17: =IF($C17<=Strambio!$D$38*Strambio!$D$39,Strambio!$D$41,0) -> 2.75 | P17: =IF($C17<=Strambio!$D$38*Strambio!$D$39,($F17+$L17+O$10),0) -> 1130.8137
A18: =YEAR(D18) -> 2025 | B18: =_xlfn.FLOOR.MATH(($C18-1)/12)+1 -> 1 | C18: =C17+1 -> 9 | D18: =EDATE(Strambio!$D$40,$C18-1) -> 45958 | E18: =SUMIFS(Strambio!$D:$D,Strambio!$B:$B,"Mutuo1",Strambio!$C:$C,"Tasso",Strambio!$E:$E,"<="&$D18,Strambio!$F:$F,">="&$D18) -> 0.0272 | F18: =IF($C18<=Strambio!$D$38*Strambio!$D$39,PMT($E18/Strambio!$D$38,Strambio!$D$38*Strambio!$D$39-$C17,-$K17),0) -> 1128.0637 | G18: =IF($C18<=Strambio!$D$38*Strambio!$D$39,$K17*$E18/Strambio!$D$38,0) -> 460.93277 | H18: =IF($C18<=Strambio!$D$38*Strambio!$D$39,$F18-$G18,0) -> 667.13092 | I18: =SUMIFS(Strambio!$D:$D,Strambio!$B:$B,"Mutuo1",Strambio!$C:$C,"Rimborso",Strambio!$E:$E,"<="&$D18,Strambio!$F:$F,">="&$D18) -> 0 | J18: =IF($C18<=Strambio!$D$38*Strambio!$D$39,H18+I18,0) -> 667.13092 | K18: =IF($C18<=Strambio!$D$38*Strambio!$D$39,($K17-$H18-$I18),0) -> 202685.56 | L18: 0 | M18: =IF($C18<=Strambio!$D$38*Strambio!$D$39,$G18+$L18,0) -> 460.93277 | N18: =IF($C18<=Strambio!$D$38*Strambio!$D$39,$N17+L18+$G18,0) -> 4202.424 | O18: =IF($C18<=Strambio!$D$38*Strambio!$D$39,Strambio!$D$41,0) -> 2.75 | P18: =IF($C18<=Strambio!$D$38*Strambio!$D$39,($F18+$L18+O$10),0) -> 1130.8137
A19: =YEAR(D19) -> 2025 | B19: =_xlfn.FLOOR.MATH(($C19-1)/12)+1 -> 1 | C19: =C18+1 -> 10 | D19: =EDATE(Strambio!$D$40,$C19-1) -> 45989 | E19: =SUMIFS(Strambio!$D:$D,Strambio!$B:$B,"Mutuo1",Strambio!$C:$C,"Tasso",Strambio!$E:$E,"<="&$D19,Strambio!$F:$F,">="&$D19) -> 0.0272 | F19: =IF($C19<=Strambio!$D$38*Strambio!$D$39,PMT($E19/Strambio!$D$38,Strambio!$D$38*Strambio!$D$39-$C18,-$K18),0) -> 1128.0637 | G19: =IF($C19<=Strambio!$D$38*Strambio!$D$39,$K18*$E19/Strambio!$D$38,0) -> 459.4206 | H19: =IF($C19<=Strambio!$D$38*Strambio!$D$39,$F19-$G19,0) -> 668.64308 | I19: =SUMIFS(Strambio!$D:$D,Strambio!$B:$B,"Mutuo1",Strambio!$C:$C,"Rimborso",Strambio!$E:$E,"<="&$D19,Strambio!$F:$F,">="&$D19) -> 0 | J19: =IF($C19<=Strambio!$D$38*Strambio!$D$39,H19+I19,0) -> 668.64308 | K19: =IF($C19<=Strambio!$D$38*Strambio!$D$39,($K18-$H19-$I19),0) -> 202016.92 | L19: 0 | M19: =IF($C19<=Strambio!$D$38*Strambio!$D$39,$G19+$L19,0) -> 459.4206 | N19: =IF($C19<=Strambio!$D$38*Strambio!$D$39,$N18+L19+$G19,0) -> 4661.8446 | O19: =IF($C19<=Strambio!$D$38*Strambio!$D$39,Strambio!$D$41,0) -> 2.75 | P19: =IF($C19<=Strambio!$D$38*Strambio!$D$39,($F19+$L19+O$10),0) -> 1130.8137
A20: =YEAR(D20) -> 2025 | B20: =_xlfn.FLOOR.MATH(($C20-1)/12)+1 -> 1 | C20: =C19+1 -> 11 | D20: =EDATE(Strambio!$D$40,$C20-1) -> 46019 | E20: =SUMIFS(Strambio!$D:$D,Strambio!$B:$B,"Mutuo1",Strambio!$C:$C,"Tasso",Strambio!$E:$E,"<="&$D20,Strambio!$F:$F,">="&$D20) -> 0.0272 | F20: =IF($C20<=Strambio!$D$38*Strambio!$D$39,PMT($E20/Strambio!$D$38,Strambio!$D$38*Strambio!$D$39-$C19,-$K19),0) -> 1128.0637 | G20: =IF($C20<=Strambio!$D$38*Strambio!$D$39,$K19*$E20/Strambio!$D$38,0) -> 457.90501 | H20: =IF($C20<=Strambio!$D$38*Strambio!$D$39,$F20-$G20,0) -> 670.15867 | I20: =SUMIFS(Strambio!$D:$D,Strambio!$B:$B,"Mutuo1",Strambio!$C:$C,"Rimborso",Strambio!$E:$E,"<="&$D20,Strambio!$F:$F,">="&$D20) -> 0 | J20: =IF($C20<=Strambio!$D$38*Strambio!$D$39,H20+I20,0) -> 670.15867 | K20: =IF($C20<=Strambio!$D$38*Strambio!$D$39,($K19-$H20-$I20),0) -> 201346.76 | L20: 0 | M20: =IF($C20<=Strambio!$D$38*Strambio!$D$39,$G20+$L20,0) -> 457.90501 | N20: =IF($C20<=Strambio!$D$38*Strambio!$D$39,$N19+L20+$G20,0) -> 5119.7497 | O20: =IF($C20<=Strambio!$D$38*Strambio!$D$39,Strambio!$D$41,0) -> 2.75 | P20: =IF($C20<=Strambio!$D$38*Strambio!$D$39,($F20+$L20+O$10),0) -> 1130.8137
A21: =YEAR(D21) -> 2026 | B21: =_xlfn.FLOOR.MATH(($C21-1)/12)+1 -> 1 | C21: =C20+1 -> 12 | D21: =EDATE(Strambio!$D$40,$C21-1) -> 46050 | E21: =SUMIFS(Strambio!$D:$D,Strambio!$B:$B,"Mutuo1",Strambio!$C:$C,"Tasso",Strambio!$E:$E,"<="&$D21,Strambio!$F:$F,">="&$D21) -> 0.0272 | F21: =IF($C21<=Strambio!$D$38*Strambio!$D$39,PMT($E21/Strambio!$D$38,Strambio!$D$38*Strambio!$D$39-$C20,-$K20),0) -> 1128.0637 | G21: =IF($C21<=Strambio!$D$38*Strambio!$D$39,$K20*$E21/Strambio!$D$38,0) -> 456.38599 | H21: =IF($C21<=Strambio!$D$38*Strambio!$D$39,$F21-$G21,0) -> 671.6777 | I21: =SUMIFS(Strambio!$D:$D,Strambio!$B:$B,"Mutuo1",Strambio!$C:$C,"Rimborso",Strambio!$E:$E,"<="&$D21,Strambio!$F:$F,">="&$D21) -> 0 | J21: =IF($C21<=Strambio!$D$38*Strambio!$D$39,H21+I21,0) -> 671.6777 | K21: =IF($C21<=Strambio!$D$38*Strambio!$D$39,($K20-$H21-$I21),0) -> 200675.08 | L21: 0 | M21: =IF($C21<=Strambio!$D$38*Strambio!$D$39,$G21+$L21,0) -> 456.38599 | N21: =IF($C21<=Strambio!$D$38*Strambio!$D$39,$N20+L21+$G21,0) -> 5576.1356 | O21: =IF($C21<=Strambio!$D$38*Strambio!$D$39,Strambio!$D$41,0) -> 2.75 | P21: =IF($C21<=Strambio!$D$38*Strambio!$D$39,($F21+$L21+O$10),0) -> 1130.8137
... A309: =YEAR(D309) -> 2050 | B309: =_xlfn.FLOOR.MATH(($C309-1)/12)+1 -> 25 | C309: =C308+1 -> 300 | D309: =EDATE(Strambio!$D$40,$C309-1) -> 54816 | E309: =SUMIFS(Strambio!$D:$D,Strambio!$B:$B,"Mutuo1",Strambio!$C:$C,"Tasso",Strambio!$E:$E,"<="&$D309,Strambio!$F:$F,">="&$D309) -> 0 | F309: =IF($C309<=Strambio!$D$38*Strambio!$D$39,PMT($E309/Strambio!$D$38,Strambio!$D$38*Strambio!$D$39-$C308,-$K308),0) -> 0 | G309: =IF($C309<=Strambio!$D$38*Strambio!$D$39,$K308*$E309/Strambio!$D$38,0) -> 0 | H309: =IF($C309<=Strambio!$D$38*Strambio!$D$39,$F309-$G309,0) -> 0 | I309: =SUMIFS(Strambio!$D:$D,Strambio!$B:$B,"Mutuo1",Strambio!$C:$C,"Rimborso",Strambio!$E:$E,"<="&$D309,Strambio!$F:$F,">="&$D309) -> 0 | J309: =IF($C309<=Strambio!$D$38*Strambio!$D$39,H309+I309,0) -> 0 | K309: =IF($C309<=Strambio!$D$38*Strambio!$D$39,($K308-$H309-$I309),0) -> 0 | L309: 0 | M309: =IF($C309<=Strambio!$D$38*Strambio!$D$39,$G309+$L309,0) -> 0 | N309: =IF($C309<=Strambio!$D$38*Strambio!$D$39,$N308+L309+$G309,0) -> 0 | O309: =IF($C309<=Strambio!$D$38*Strambio!$D$39,Strambio!$D$41,0) -> 0 | P309: =IF($C309<=Strambio!$D$38*Strambio!$D$39,($F309+$L309+O$10),0) -> 0

Sheet FOI
N1: =I94/2 -> 0.02761576 | O1: =I106 -> 0.0087784286 | P1: =I118 -> 0.017173592
B2: https://www.comolecco.camcom.it/archivio5_notizie_0_690.html | M2: =100 -> 100 | N2: =M2*(1+N1) -> 102.76158 | O2: =N2*(1+O1) -> 103.66366 | P2: =O2*(1+P1) -> 105.44394
C4: (1) | D4: numero giorni effettivi del mese
G6: Inflazione | P6: Indice di riferimento
A7: Mese | B7: Anno | C7: dd (1) | D7: Mese | E7: Indice FOI ex tab | G7: Var. mensile | H7: Var. annuale | I7: Var. media | J7: Prev. Inflazione | L7: m-3 | M7: m-2 | N7: I(m-3) | O7: I(m-2) | P7: 1 | Q7: 2 | R7: 3 | S7: 4 | T7: 5 | U7: 6 | V7: 7 | W7: 8 | X7: 9 | Y7: 10 | Z7: 11 | AA7: 12 | AB7: 13 | AC7: 14 | AD7: 15 | AE7: 16 | AF7: 17 | AG7: 18 | AH7: 19 | AI7: 20 | AJ7: 21 | AK7: 22 | AL7: 23 | AM7: 24 | AN7: 25 | AO7: 26 | AP7: 27 | AQ7: 28 | AR7: 29 | AS7: 30 | AT7: 31
A8: =MONTH(D8) -> 10 | B8: =YEAR(D8) -> 2016 | D8: 42644 | E8: 100
A9: =MONTH(D9) -> 11 | B9: =YEAR(D9) -> 2016 | D9: 42675 | E9: 100
A10: =MONTH(D10) -> 12 | B10: =YEAR(D10) -> 2016 | D10: 42705 | E10: 100.3
A11: =MONTH(D11) -> 1 | B11: =YEAR(D11) -> 2017 | C11: 31 | D11: 42736 | E11: 100.6 | L11: =EDATE($D11,-3) -> 42644 | M11: =EDATE($D11,-2) -> 42675 | N11: =SUMIFS($E:$E,$D:$D,L11) -> 100 | O11: =SUMIFS($E:$E,$D:$D,M11) -> 100 | P11: =$N11+($O11-$N11)/$C11*(P$7-1) -> 100 | Q11: =$N11+($O11-$N11)/$C11*(Q$7-1) -> 100 | R11: =$N11+($O11-$N11)/$C11*(R$7-1) -> 100 | S11: =$N11+($O11-$N11)/$C11*(S$7-1) -> 100 | T11: =$N11+($O11-$N11)/$C11*(T$7-1) -> 100 | U11: =$N11+($O11-$N11)/$C11*(U$7-1) -> 100 | V11: =$N11+($O11-$N11)/$C11*(V$7-1) -> 100 | W11: =$N11+($O11-$N11)/$C11*(W$7-1) -> 100 | ... AT11: =$N11+($O11-$N11)/$C11*(AT$7-1) -> 100
A12: =MONTH(D12) -> 2 | B12: =YEAR(D12) -> 2017 | C12: 28 | D12: 42767 | E12: 101 | G12: =(E12-E11)/E11 -> 0.0039761431 | L12: =EDATE($D12,-3) -> 42675 | M12: =EDATE($D12,-2) -> 42705 | N12: =SUMIFS($E:$E,$D:$D,L12) -> 100 | O12: =SUMIFS($E:$E,$D:$D,M12) -> 100.3 | P12: =$N12+($O12-$N12)/$C12*(P$7-1) -> 100 | Q12: =$N12+($O12-$N12)/$C12*(Q$7-1) -> 100.01071 | R12: =$N12+($O12-$N12)/$C12*(R$7-1) -> 100.02143 | S12: =$N12+($O12-$N12)/$C12*(S$7-1) -> 100.03214 | T12: =$N12+($O12-$N12)/$C12*(T$7-1) -> 100.04286 | U12: =$N12+($O12-$N12)/$C12*(U$7-1) -> 100.05357 | V12: =$N12+($O12-$N12)/$C12*(V$7-1) -> 100.06429 | W12: =$N12+($O12-$N12)/$C12*(W$7-1) -> 100.075 | ... AT12: =$N12+($O12-$N12)/$C12*(AT$7-1) -> 100.32143
A13: =MONTH(D13) -> 3 | B13: =YEAR(D13) -> 2017 | C13: 31 | D13: 42795 | E13: 101 | G13: =(E13-E12)/E12 -> 0 | L13: =EDATE($D13,-3) -> 42705 | M13: =EDATE($D13,-2) -> 42736 | N13: =SUMIFS($E:$E,$D:$D,L13) -> 100.3 | O13: =SUMIFS($E:$E,$D:$D,M13) -> 100.6 | P13: =$N13+($O13-$N13)/$C13*(P$7-1) -> 100.3 | Q13: =$N13+($O13-$N13)/$C13*(Q$7-1) -> 100.30968 | R13: =$N13+($O13-$N13)/$C13*(R$7-1) -> 100.31935 | S13: =$N13+($O13-$N13)/$C13*(S$7-1) -> 100.32903 | T13: =$N13+($O13-$N13)/$C13*(T$7-1) -> 100.33871 | U13: =$N13+($O13-$N13)/$C13*(U$7-1) -> 100.34839 | V13: =$N13+($O13-$N13)/$C13*(V$7-1) -> 100.35806 | W13: =$N13+($O13-$N13)/$C13*(W$7-1) -> 100.36774 | ... AT13: =$N13+($O13-$N13)/$C13*(AT$7-1) -> 100.59032
A14: =MONTH(D14) -> 4 | B14: =YEAR(D14) -> 2017 | C14: 30 | D14: 42826 | E14: 101.3 | G14: =(E14-E13)/E13 -> 0.002970297 | L14: =EDATE($D14,-3) -> 42736 | M14: =EDATE($D14,-2) -> 42767 | N14: =SUMIFS($E:$E,$D:$D,L14) -> 100.6 | O14: =SUMIFS($E:$E,$D:$D,M14) -> 101 | P14: =$N14+($O14-$N14)/$C14*(P$7-1) -> 100.6 | Q14: =$N14+($O14-$N14)/$C14*(Q$7-1) -> 100.61333 | R14: =$N14+($O14-$N14)/$C14*(R$7-1) -> 100.62667 | S14: =$N14+($O14-$N14)/$C14*(S$7-1) -> 100.64 | T14: =$N14+($O14-$N14)/$C14*(T$7-1) -> 100.65333 | U14: =$N14+($O14-$N14)/$C14*(U$7-1) -> 100.66667 | V14: =$N14+($O14-$N14)/$C14*(V$7-1) -> 100.68 | W14: =$N14+($O14-$N14)/$C14*(W$7-1) -> 100.69333 | ... AT14: =$N14+($O14-$N14)/$C14*(AT$7-1) -> 101
A15: =MONTH(D15) -> 5 | B15: =YEAR(D15) -> 2017 | C15: 31 | D15: 42856 | E15: 101.1 | G15: =(E15-E14)/E14 -> -0.0019743337 | L15: =EDATE($D15,-3) -> 42767 | M15: =EDATE($D15,-2) -> 42795 | N15: =SUMIFS($E:$E,$D:$D,L15) -> 101 | O15: =SUMIFS($E:$E,$D:$D,M15) -> 101 | P15: =$N15+($O15-$N15)/$C15*(P$7-1) -> 101 | Q15: =$N15+($O15-$N15)/$C15*(Q$7-1) -> 101 | R15: =$N15+($O15-$N15)/$C15*(R$7-1) -> 101 | S15: =$N15+($O15-$N15)/$C15*(S$7-1) -> 101 | T15: =$N15+($O15-$N15)/$C15*(T$7-1) -> 101 | U15: =$N15+($O15-$N15)/$C15*(U$7-1) -> 101 | V15: =$N15+($O15-$N15)/$C15*(V$7-1) -> 101 | W15: =$N15+($O15-$N15)/$C15*(W$7-1) -> 101 | ... AT15: =$N15+($O15-$N15)/$C15*(AT$7-1) -> 101
A16: =MONTH(D16) -> 6 | B16: =YEAR(D16) -> 2017 | C16: 30 | D16: 42887 | E16: 101 | G16: =(E16-E15)/E15 -> -0.00098911968 | L16: =EDATE($D16,-3) -> 42795 | M16: =EDATE($D16,-2) -> 42826 | N16: =SUMIFS($E:$E,$D:$D,L16) -> 101 | O16: =SUMIFS($E:$E,$D:$D,M16) -> 101.3 | P16: =$N16+($O16-$N16)/$C16*(P$7-1) -> 101 | Q16: =$N16+($O16-$N16)/$C16*(Q$7-1) -> 101.01 | R16: =$N16+($O16-$N16)/$C16*(R$7-1) -> 101.02 | S16: =$N16+($O16-$N16)/$C16*(S$7-1) -> 101.03 | T16: =$N16+($O16-$N16)/$C16*(T$7-1) -> 101.04 | U16: =$N16+($O16-$N16)/$C16*(U$7-1) -> 101.05 | V16: =$N16+($O16-$N16)/$C16*(V$7-1) -> 101.06 | W16: =$N16+($O16-$N16)/$C16*(W$7-1) -> 101.07 | ... AT16: =$N16+($O16-$N16)/$C16*(AT$7-1) -> 101.3
A17: =MONTH(D17) -> 7 | B17: =YEAR(D17) -> 2017 | C17: 31 | D17: 42917 | E17: 101 | G17: =(E17-E16)/E16 -> 0 | L17: =EDATE($D17,-3) -> 42826 | M17: =EDATE($D17,-2) -> 42856 | N17: =SUMIFS($E:$E,$D:$D,L17) -> 101.3 | O17: =SUMIFS($E:$E,$D:$D,M17) -> 101.1 | P17: =$N17+($O17-$N17)/$C17*(P$7-1) -> 101.3 | Q17: =$N17+($O17-$N17)/$C17*(Q$7-1) -> 101.29355 | R17: =$N17+($O17-$N17)/$C17*(R$7-1) -> 101.2871 | S17: =$N17+($O17-$N17)/$C17*(S$7-1) -> 101.28065 | T17: =$N17+($O17-$N17)/$C17*(T$7-1) -> 101.27419 | U17: =$N17+($O17-$N17)/$C17*(U$7-1) -> 101.26774 | V17: =$N17+($O17-$N17)/$C17*(V$7-1) -> 101.26129 | W17: =$N17+($O17-$N17)/$C17*(W$7-1) -> 101.25484 | ... AT17: =$N17+($O17-$N17)/$C17*(AT$7-1) -> 101.10645
A18: =MONTH(D18) -> 8 | B18: =YEAR(D18) -> 2017 | C18: 31 | D18: 42948 | E18: 101.4 | G18: =(E18-E17)/E17 -> 0.003960396 | L18: =EDATE($D18,-3) -> 42856 | M18: =EDATE($D18,-2) -> 42887 | N18: =SUMIFS($E:$E,$D:$D,L18) -> 101.1 | O18: =SUMIFS($E:$E,$D:$D,M18) -> 101 | P18: =$N18+($O18-$N18)/$C18*(P$7-1) -> 101.1 | Q18: =$N18+($O18-$N18)/$C18*(Q$7-1) -> 101.09677 | R18: =$N18+($O18-$N18)/$C18*(R$7-1) -> 101.09355 | S18: =$N18+($O18-$N18)/$C18*(S$7-1) -> 101.09032 | T18: =$N18+($O18-$N18)/$C18*(T$7-1) -> 101.0871 | U18: =$N18+($O18-$N18)/$C18*(U$7-1) -> 101.08387 | V18: =$N18+($O18-$N18)/$C18*(V$7-1) -> 101.08065 | W18: =$N18+($O18-$N18)/$C18*(W$7-1) -> 101.07742 | ... AT18: =$N18+($O18-$N18)/$C18*(AT$7-1) -> 101.00323
A19: =MONTH(D19) -> 9 | B19: =YEAR(D19) -> 2017 | C19: 30 | D19: 42979 | E19: 101.1 | G19: =(E19-E18)/E18 -> -0.0029585799 | L19: =EDATE($D19,-3) -> 42887 | M19: =EDATE($D19,-2) -> 42917 | N19: =SUMIFS($E:$E,$D:$D,L19) -> 101 | O19: =SUMIFS($E:$E,$D:$D,M19) -> 101 | P19: =$N19+($O19-$N19)/$C19*(P$7-1) -> 101 | Q19: =$N19+($O19-$N19)/$C19*(Q$7-1) -> 101 | R19: =$N19+($O19-$N19)/$C19*(R$7-1) -> 101 | S19: =$N19+($O19-$N19)/$C19*(S$7-1) -> 101 | T19: =$N19+($O19-$N19)/$C19*(T$7-1) -> 101 | U19: =$N19+($O19-$N19)/$C19*(U$7-1) -> 101 | V19: =$N19+($O19-$N19)/$C19*(V$7-1) -> 101 | W19: =$N19+($O19-$N19)/$C19*(W$7-1) -> 101 | ... AT19: =$N19+($O19-$N19)/$C19*(AT$7-1) -> 101
A20: =MONTH(D20) -> 10 | B20: =YEAR(D20) -> 2017 | C20: 31 | D20: 43009 | E20: 100.9 | G20: =(E20-E19)/E19 -> -0.0019782394 | L20: =EDATE($D20,-3) -> 42917 | M20: =EDATE($D20,-2) -> 42948 | N20: =SUMIFS($E:$E,$D:$D,L20) -> 101 | O20: =SUMIFS($E:$E,$D:$D,M20) -> 101.4 | P20: =$N20+($O20-$N20)/$C20*(P$7-1) -> 101 | Q20: =$N20+($O20-$N20)/$C20*(Q$7-1) -> 101.0129 | R20: =$N20+($O20-$N20)/$C20*(R$7-1) -> 101.02581 | S20: =$N20+($O20-$N20)/$C20*(S$7-1) -> 101.03871 | T20: =$N20+($O20-$N20)/$C20*(T$7-1) -> 101.05161 | U20: =$N20+($O20-$N20)/$C20*(U$7-1) -> 101.06452 | V20: =$N20+($O20-$N20)/$C20*(V$7-1) -> 101.07742 | W20: =$N20+($O20-$N20)/$C20*(W$7-1) -> 101.09032 | ... AT20: =$N20+($O20-$N20)/$C20*(AT$7-1) -> 101.3871
A21: =MONTH(D21) -> 11 | B21: =YEAR(D21) -> 2017 | C21: 30 | D21: 43040 | E21: 100.8 | G21: =(E21-E20)/E20 -> -0.00099108028 | L21: =EDATE($D21,-3) -> 42948 | M21: =EDATE($D21,-2) -> 42979 | N21: =SUMIFS($E:$E,$D:$D,L21) -> 101.4 | O21: =SUMIFS($E:$E,$D:$D,M21) -> 101.1 | P21: =$N21+($O21-$N21)/$C21*(P$7-1) -> 101.4 | Q21: =$N21+($O21-$N21)/$C21*(Q$7-1) -> 101.39 | R21: =$N21+($O21-$N21)/$C21*(R$7-1) -> 101.38 | S21: =$N21+($O21-$N21)/$C21*(S$7-1) -> 101.37 | T21: =$N21+($O21-$N21)/$C21*(T$7-1) -> 101.36 | U21: =$N21+($O21-$N21)/$C21*(U$7-1) -> 101.35 | V21: =$N21+($O21-$N21)/$C21*(V$7-1) -> 101.34 | W21: =$N21+($O21-$N21)/$C21*(W$7-1) -> 101.33 | ... AT21: =$N21+($O21-$N21)/$C21*(AT$7-1) -> 101.1
A22: =MONTH(D22) -> 12 | B22: =YEAR(D22) -> 2017 | C22: 31 | D22: 43070 | E22: 101.1 | G22: =(E22-E21)/E21 -> 0.0029761905 | L22: =EDATE($D22,-3) -> 42979 | M22: =EDATE($D22,-2) -> 43009 | N22: =SUMIFS($E:$E,$D:$D,L22) -> 101.1 | O22: =SUMIFS($E:$E,$D:$D,M22) -> 100.9 | P22: =$N22+($O22-$N22)/$C22*(P$7-1) -> 101.1 | Q22: =$N22+($O22-$N22)/$C22*(Q$7-1) -> 101.09355 | R22: =$N22+($O22-$N22)/$C22*(R$7-1) -> 101.0871 | S22: =$N22+($O22-$N22)/$C22*(S$7-1) -> 101.08065 | T22: =$N22+($O22-$N22)/$C22*(T$7-1) -> 101.07419 | U22: =$N22+($O22-$N22)/$C22*(U$7-1) -> 101.06774 | V22: =$N22+($O22-$N22)/$C22*(V$7-1) -> 101.06129 | W22: =$N22+($O22-$N22)/$C22*(W$7-1) -> 101.05484 | ... AT22: =$N22+($O22-$N22)/$C22*(AT$7-1) -> 100.90645
A23: =MONTH(D23) -> 1 | B23: =YEAR(D23) -> 2018 | C23: 31 | D23: 43101 | E23: 101.5 | G23: =(E23-E22)/E22 -> 0.0039564787 | H23: =(E23-E11)/E11 -> 0.0089463221 | L23: =EDATE($D23,-3) -> 43009 | M23: =EDATE($D23,-2) -> 43040 | N23: =SUMIFS($E:$E,$D:$D,L23) -> 100.9 | O23: =SUMIFS($E:$E,$D:$D,M23) -> 100.8 | P23: =$N23+($O23-$N23)/$C23*(P$7-1) -> 100.9 | Q23: =$N23+($O23-$N23)/$C23*(Q$7-1) -> 100.89677 | R23: =$N23+($O23-$N23)/$C23*(R$7-1) -> 100.89355 | S23: =$N23+($O23-$N23)/$C23*(S$7-1) -> 100.89032 | T23: =$N23+($O23-$N23)/$C23*(T$7-1) -> 100.8871 | U23: =$N23+($O23-$N23)/$C23*(U$7-1) -> 100.88387 | V23: =$N23+($O23-$N23)/$C23*(V$7-1) -> 100.88065 | W23: =$N23+($O23-$N23)/$C23*(W$7-1) -> 100.87742 | ... AT23: =$N23+($O23-$N23)/$C23*(AT$7-1) -> 100.80323
A24: =MONTH(D24) -> 2 | B24: =YEAR(D24) -> 2018 | C24: 28 | D24: 43132 | E24: 101.5 | G24: =(E24-E23)/E23 -> 0 | H24: =(E24-E12)/E12 -> 0.004950495 | L24: =EDATE($D24,-3) -> 43040 | M24: =EDATE($D24,-2) -> 43070 | N24: =SUMIFS($E:$E,$D:$D,L24) -> 100.8 | O24: =SUMIFS($E:$E,$D:$D,M24) -> 101.1 | P24: =$N24+($O24-$N24)/$C24*(P$7-1) -> 100.8 | Q24: =$N24+($O24-$N24)/$C24*(Q$7-1) -> 100.81071 | R24: =$N24+($O24-$N24)/$C24*(R$7-1) -> 100.82143 | S24: =$N24+($O24-$N24)/$C24*(S$7-1) -> 100.83214 | T24: =$N24+($O24-$N24)/$C24*(T$7-1) -> 100.84286 | U24: =$N24+($O24-$N24)/$C24*(U$7-1) -> 100.85357 | V24: =$N24+($O24-$N24)/$C24*(V$7-1) -> 100.86429 | W24: =$N24+($O24-$N24)/$C24*(W$7-1) -> 100.875 | ... AT24: =$N24+($O24-$N24)/$C24*(AT$7-1) -> 101.12143
A25: =MONTH(D25) -> 3 | B25: =YEAR(D25) -> 2018 | C25: 31 | D25: 43160 | E25: 101.7 | G25: =(E25-E24)/E24 -> 0.0019704433 | H25: =(E25-E13)/E13 -> 0.0069306931 | L25: =EDATE($D25,-3) -> 43070 | M25: =EDATE($D25,-2) -> 43101 | N25: =SUMIFS($E:$E,$D:$D,L25) -> 101.1 | O25: =SUMIFS($E:$E,$D:$D,M25) -> 101.5 | P25: =$N25+($O25-$N25)/$C25*(P$7-1) -> 101.1 | Q25: =$N25+($O25-$N25)/$C25*(Q$7-1) -> 101.1129 | R25: =$N25+($O25-$N25)/$C25*(R$7-1) -> 101.12581 | S25: =$N25+($O25-$N25)/$C25*(S$7-1) -> 101.13871 | T25: =$N25+($O25-$N25)/$C25*(T$7-1) -> 101.15161 | U25: =$N25+($O25-$N25)/$C25*(U$7-1) -> 101.16452 | V25: =$N25+($O25-$N25)/$C25*(V$7-1) -> 101.17742 | W25: =$N25+($O25-$N25)/$C25*(W$7-1) -> 101.19032 | ... AT25: =$N25+($O25-$N25)/$C25*(AT$7-1) -> 101.4871
A26: =MONTH(D26) -> 4 | B26: =YEAR(D26) -> 2018 | C26: 30 | D26: 43191 | E26: 101.7 | G26: =(E26-E25)/E25 -> 0 | H26: =(E26-E14)/E14 -> 0.0039486673 | L26: =EDATE($D26,-3) -> 43101 | M26: =EDATE($D26,-2) -> 43132 | N26: =SUMIFS($E:$E,$D:$D,L26) -> 101.5 | O26: =SUMIFS($E:$E,$D:$D,M26) -> 101.5 | P26: =$N26+($O26-$N26)/$C26*(P$7-1) -> 101.5 | Q26: =$N26+($O26-$N26)/$C26*(Q$7-1) -> 101.5 | R26: =$N26+($O26-$N26)/$C26*(R$7-1) -> 101.5 | S26: =$N26+($O26-$N26)/$C26*(S$7-1) -> 101.5 | T26: =$N26+($O26-$N26)/$C26*(T$7-1) -> 101.5 | U26: =$N26+($O26-$N26)/$C26*(U$7-1) -> 101.5 | V26: =$N26+($O26-$N26)/$C26*(V$7-1) -> 101.5 | W26: =$N26+($O26-$N26)/$C26*(W$7-1) -> 101.5 | ... AT26: =$N26+($O26-$N26)/$C26*(AT$7-1) -> 101.5
A27: =MONTH(D27) -> 5 | B27: =YEAR(D27) -> 2018 | C27: 31 | D27: 43221 | E27: 102 | G27: =(E27-E26)/E26 -> 0.0029498525 | H27: =(E27-E15)/E15 -> 0.0089020772 | L27: =EDATE($D27,-3) -> 43132 | M27: =EDATE($D27,-2) -> 43160 | N27: =SUMIFS($E:$E,$D:$D,L27) -> 101.5 | O27: =SUMIFS($E:$E,$D:$D,M27) -> 101.7 | P27: =$N27+($O27-$N27)/$C27*(P$7-1) -> 101.5 | Q27: =$N27+($O27-$N27)/$C27*(Q$7-1) -> 101.50645 | R27: =$N27+($O27-$N27)/$C27*(R$7-1) -> 101.5129 | S27: =$N27+($O27-$N27)/$C27*(S$7-1) -> 101.51935 | T27: =$N27+($O27-$N27)/$C27*(T$7-1) -> 101.52581 | U27: =$N27+($O27-$N27)/$C27*(U$7-1) -> 101.53226 | V27: =$N27+($O27-$N27)/$C27*(V$7-1) -> 101.53871 | W27: =$N27+($O27-$N27)/$C27*(W$7-1) -> 101.54516 | ... AT27: =$N27+($O27-$N27)/$C27*(AT$7-1) -> 101.69355
A28: =MONTH(D28) -> 6 | B28: =YEAR(D28) -> 2018 | C28: 30 | D28: 43252 | E28: 102.2 | G28: =(E28-E27)/E27 -> 0.0019607843 | H28: =(E28-E16)/E16 -> 0.011881188 | L28: =EDATE($D28,-3) -> 43160 | M28: =EDATE($D28,-2) -> 43191 | N28: =SUMIFS($E:$E,$D:$D,L28) -> 101.7 | O28: =SUMIFS($E:$E,$D:$D,M28) -> 101.7 | P28: =$N28+($O28-$N28)/$C28*(P$7-1) -> 101.7 | Q28: =$N28+($O28-$N28)/$C28*(Q$7-1) -> 101.7 | R28: =$N28+($O28-$N28)/$C28*(R$7-1) -> 101.7 | S28: =$N28+($O28-$N28)/$C28*(S$7-1) -> 101.7 | T28: =$N28+($O28-$N28)/$C28*(T$7-1) -> 101.7 | U28: =$N28+($O28-$N28)/$C28*(U$7-1) -> 101.7 | V28: =$N28+($O28-$N28)/$C28*(V$7-1) -> 101.7 | W28: =$N28+($O28-$N28)/$C28*(W$7-1) -> 101.7 | ... AT28: =$N28+($O28-$N28)/$C28*(AT$7-1) -> 101.7
A29: =MONTH(D29) -> 7 | B29: =YEAR(D29) -> 2018 | C29: 31 | D29: 43282 | E29: 102.5 | G29: =(E29-E28)/E28 -> 0.0029354207 | H29: =(E29-E17)/E17 -> 0.014851485 | L29: =EDATE($D29,-3) -> 43191 | M29: =EDATE($D29,-2) -> 43221 | N29: =SUMIFS($E:$E,$D:$D,L29) -> 101.7 | O29: =SUMIFS($E:$E,$D:$D,M29) -> 102 | P29: =$N29+($O29-$N29)/$C29*(P$7-1) -> 101.7 | Q29: =$N29+($O29-$N29)/$C29*(Q$7-1) -> 101.70968 | R29: =$N29+($O29-$N29)/$C29*(R$7-1) -> 101.71935 | S29: =$N29+($O29-$N29)/$C29*(S$7-1) -> 101.72903 | T29: =$N29+($O29-$N29)/$C29*(T$7-1) -> 101.73871 | U29: =$N29+($O29-$N29)/$C29*(U$7-1) -> 101.74839 | V29: =$N29+($O29-$N29)/$C29*(V$7-1) -> 101.75806 | W29: =$N29+($O29-$N29)/$C29*(W$7-1) -> 101.76774 | ... AT29: =$N29+($O29-$N29)/$C29*(AT$7-1) -> 101.99032
A30: =MONTH(D30) -> 8 | B30: =YEAR(D30) -> 2018 | C30: 31 | D30: 43313 | E30: 102.9 | G30: =(E30-E29)/E29 -> 0.003902439 | H30: =(E30-E18)/E18 -> 0.014792899 | L30: =EDATE($D30,-3) -> 43221 | M30: =EDATE($D30,-2) -> 43252 | N30: =SUMIFS($E:$E,$D:$D,L30) -> 102 | O30: =SUMIFS($E:$E,$D:$D,M30) -> 102.2 | P30: =$N30+($O30-$N30)/$C30*(P$7-1) -> 102 | Q30: =$N30+($O30-$N30)/$C30*(Q$7-1) -> 102.00645 | R30: =$N30+($O30-$N30)/$C30*(R$7-1) -> 102.0129 | S30: =$N30+($O30-$N30)/$C30*(S$7-1) -> 102.01935 | T30: =$N30+($O30-$N30)/$C30*(T$7-1) -> 102.02581 | U30: =$N30+($O30-$N30)/$C30*(U$7-1) -> 102.03226 | V30: =$N30+($O30-$N30)/$C30*(V$7-1) -> 102.03871 | W30: =$N30+($O30-$N30)/$C30*(W$7-1) -> 102.04516 | ... AT30: =$N30+($O30-$N30)/$C30*(AT$7-1) -> 102.19355
